Workbook

Sheet Overview
A1: Silver — detailed completed-backtest workbook
A3: Purpose | B3: Reconstruct the selected strategy path from the completed backtest holding ledger, with visible holding P&L, book valuation, underlying-return decomposition, NAV reconciliation, and model checks.
A4: Holding interval | B4: Each row applies the start-date close holdings through the end-date close. Exchange holidays naturally create multi-calendar-day intervals.
A5: Template version | B5: 1
A6: Commodity scope | B6: Silver; this template version requires exactly one commodity sleeve.
A7: Mode | B7: positive = long futures only; neutral = no futures; negative = short futures only; long_and_short = both.
A8: Futures value | B8: Exchange-traded futures are carried at zero after daily settlement. Notional is exposure; economic P&L settles into the attributed cash/margin holding.
A9: Book valuation | B9: Lease and keep values are independently reconstructed from attributed holdings and from opening value + accumulated P&L + external/rebalancing transfers.
A10: Returns | B10: Standalone book return uses that book's start value. Contribution uses total lease + keep start value. Total return is reconstructed as underlying price change compounded with the combined book return quoted in the underlying.
A11: Prices | B11: A future's spot fields contain the actual commodity spot quote. Futures notional and quantity do not rescale that spot price. The normalized underlying index is shown separately.
A13: Selected result summary
A14: First holding date | B14: 25205
A15: Final interval end | B15: 25568
A16: Holding intervals | B16: 242
A17: Maximum simultaneous ledger holdings | B17: 10
A18: Ending NAV | B18: 2.0433695
A19: Portfolio rebalancing | B19: daily

Sheet Parameters
A1: Silver — completed-backtest parameters
A3: Parameter path | B3: Saved value | C3: Use | D3: Notes
A4: weight_silver | B4: 100 | C4: Exact completed-run input | D4: Nested commodity parameters are expanded for auditability.
A5: weight_gold | B5: 0 | C5: Exact completed-run input | D5: Nested commodity parameters are expanded for auditability.
A6: weight_sp500 | B6: 0 | C6: Exact completed-run input | D6: Nested commodity parameters are expanded for auditability.
A7: weight_btc | B7: 0 | C7: Exact completed-run input | D7: Nested commodity parameters are expanded for auditability.
A8: weight_treasury | B8: 0 | C8: Exact completed-run input | D8: Nested commodity parameters are expanded for auditability.
A9: portfolio_rebalancing | B9: daily | C9: Exact completed-run input | D9: Nested commodity parameters are expanded for auditability.
A10: reactivity | B10: same_day | C10: Exact completed-run input | D10: Nested commodity parameters are expanded for auditability.
A11: min_days | B11: 10 | C11: Exact completed-run input | D11: Nested commodity parameters are expanded for auditability.
A12: roll_only_if_better | B12: true | C12: Exact completed-run input | D12: Nested commodity parameters are expanded for auditability.
A13: force_roll_at_min_days | B13: true | C13: Exact completed-run input | D13: Nested commodity parameters are expanded for auditability.
A14: long_allocation_half_life_days | B14: 0 | C14: Exact completed-run input | D14: Nested commodity parameters are expanded for auditability.
... A167: commodity_parameters.sp500.max_short_fraction_of_long_leg | B167: 50 | C167: Exact completed-run input | D167: Nested commodity parameters are expanded for auditability.

Sheet Daily Holdings
A1: Interval and NAV | M1: Underlying and return reconstruction | AH1: Book valuation and roll-forward | BD1: Detailed return contributions | BK1: Holding 1 | CF1: Holding 2 | DA1: Holding 3 | DV1: Holding 4 | EQ1: Holding 5 | FL1: Holding 6 | GG1: Holding 7 | HB1: Holding 8 | HW1: Holding 9 | IR1: Holding 10
A2: Start date | B2: End date | C2: Elapsed days | D2: Signal date | E2: Mode | F2: Start NAV | G2: Source total daily return | H2: Calculated holdings return | I2: Holdings return difference | J2: Formula end NAV | K2: Engine end NAV | L2: NAV difference | M2: Underlying start spot | N2: Underlying end spot | O2: Underlying index start | P2: Underlying index end | Q2: Underlying price change | R2: Lease book start — holdings sum | S2: Lease book end — holdings sum | T2: Keep book start — holdings sum | U2: Keep book end — holdings sum | V2: Lease book start in underlying | W2: Lease book end in underlying | X2: Keep book start in underlying | Y2: Keep book end in underlying | Z2: Total books start in underlying | AA2: Lease standalone return in underlying | AB2: Lease contribution to combined book return | AC2: Keep standalone return in underlying | AD2: Keep contribution to combined book return | AE2: Combined books return in underlying | AF2: Reconstructed total daily return | AG2: Underlying/book return difference | AH2: Lease book interval P&L | AI2: Keep book interval P&L | AJ2: Lease internal transfer check | AK2: Keep internal transfer check | AL2: Lease external/rebalancing transfer | AM2: Keep external/rebalancing transfer | AN2: Lease opening value | AO2: Lease accumulated P&L | AP2: Lease accumulated external transfers | AQ2: Lease book end — roll-forward | AR2: Lease holdings vs roll-forward difference | AS2: Keep opening value | AT2: Keep accumulated P&L | AU2: Keep accumulated external transfers | AV2: Keep book end — roll-forward | AW2: Keep holdings vs roll-forward difference | AX2: Lease book start — engine audit | AY2: Lease book end — engine audit | AZ2: Lease book engine audit difference | BA2: Keep book start — engine audit | BB2: Keep book end — engine audit | BC2: Keep book engine audit difference | BD2: Direct/replicating contribution | BE2: Treasury contribution | BF2: Futures contribution | BG2: Cash/financing contribution | BH2: Detailed contribution sum | BI2: Detailed return difference | BJ2: Actual holding count | BK2: Name | BL2: Type | BM2: Book | BN2: Side | BO2: Contract type | BP2: Start price | BQ2: End price | BR2: Quantity / units | BS2: Position (% NAV) | BT2: Value / notional | BU2: Start value | BV2: End value | BW2: Economic P&L | BX2: Internal transfer | BY2: Spot price — start | BZ2: Spot price — end | CA2: Premium | CB2: Matched USD rate | CC2: Lease rate | CD2: Maturity (days) | CE2: Return contribution | CF2: Name | CG2: Type | CH2: Book | CI2: Side | CJ2: Contract type | CK2: Start price | CL2: End price | CM2: Quantity / units | CN2: Position (% NAV) | CO2: Value / notional | CP2: Start value | CQ2: End value | CR2: Economic P&L | CS2: Internal transfer | CT2: Spot price — start | CU2: Spot price — end | CV2: Premium | CW2: Matched USD rate | CX2: Lease rate | CY2: Maturity (days) | CZ2: Return contribution | DA2: Name | DB2: Type | DC2: Book | DD2: Side | DE2: Contract type | DF2: Start price | DG2: End price | DH2: Quantity / units | DI2: Position (% NAV) | DJ2: Value / notional | DK2: Start value | DL2: End value | DM2: Economic P&L | DN2: Internal transfer | DO2: Spot price — start | DP2: Spot price — end | DQ2: Premium | DR2: Matched USD rate | DS2: Lease rate | DT2: Maturity (days) | DU2: Return contribution | DV2: Name | DW2: Type | DX2: Book | DY2: Side | DZ2: Contract type | EA2: Start price | EB2: End price | EC2: Quantity / units | ED2: Position (% NAV) | EE2: Value / notional | EF2: Start value | EG2: End value | EH2: Economic P&L | EI2: Internal transfer | EJ2: Spot price — start | EK2: Spot price — end | EL2: Premium | EM2: Matched USD rate | EN2: Lease rate | EO2: Maturity (days) | EP2: Return contribution | EQ2: Name | ER2: Type | ES2: Book | ET2: Side | EU2: Contract type | EV2: Start price | EW2: End price | EX2: Quantity / units | EY2: Position (% NAV) | EZ2: Value / notional | FA2: Start value | FB2: End value | FC2: Economic P&L | FD2: Internal transfer | FE2: Spot price — start | FF2: Spot price — end | FG2: Premium | FH2: Matched USD rate | FI2: Lease rate | FJ2: Maturity (days) | FK2: Return contribution | FL2: Name | FM2: Type | FN2: Book | FO2: Side | FP2: Contract type | FQ2: Start price | FR2: End price | FS2: Quantity / units | FT2: Position (% NAV) | FU2: Value / notional | FV2: Start value | FW2: End value | FX2: Economic P&L | FY2: Internal transfer | FZ2: Spot price — start | GA2: Spot price — end | GB2: Premium | GC2: Matched USD rate | GD2: Lease rate | GE2: Maturity (days) | GF2: Return contribution | GG2: Name | GH2: Type | GI2: Book | GJ2: Side | GK2: Contract type | GL2: Start price | GM2: End price | GN2: Quantity / units | GO2: Position (% NAV) | GP2: Value / notional | GQ2: Start value | GR2: End value | GS2: Economic P&L | GT2: Internal transfer | GU2: Spot price — start | GV2: Spot price — end | GW2: Premium | GX2: Matched USD rate | GY2: Lease rate | GZ2: Maturity (days) | HA2: Return contribution | HB2: Name | HC2: Type | HD2: Book | HE2: Side | HF2: Contract type | HG2: Start price | HH2: End price | HI2: Quantity / units | HJ2: Position (% NAV) | HK2: Value / notional | HL2: Start value | HM2: End value | HN2: Economic P&L | HO2: Internal transfer | HP2: Spot price — start | HQ2: Spot price — end | HR2: Premium | HS2: Matched USD rate | HT2: Lease rate | HU2: Maturity (days) | HV2: Return contribution | HW2: Name | HX2: Type | HY2: Book | HZ2: Side | IA2: Contract type | IB2: Start price | IC2: End price | ID2: Quantity / units | IE2: Position (% NAV) | IF2: Value / notional | IG2: Start value | IH2: End value | II2: Economic P&L | IJ2: Internal transfer | IK2: Spot price — start | IL2: Spot price — end | IM2: Premium | IN2: Matched USD rate | IO2: Lease rate | IP2: Maturity (days) | IQ2: Return contribution | IR2: Name | IS2: Type | IT2: Book | IU2: Side | IV2: Contract type | IW2: Start price | IX2: End price | IY2: Quantity / units | IZ2: Position (% NAV) | JA2: Value / notional | JB2: Start value | JC2: End value | JD2: Economic P&L | JE2: Internal transfer | JF2: Spot price — start | JG2: Spot price — end | JH2: Premium | JI2: Matched USD rate | JJ2: Lease rate | JK2: Maturity (days) | JL2: Return contribution
A3: 25205 | B3: 25206 | C3: =B3-A3 -> 1 | D3: 25205 | E3: positive | F3: 1 | G3: 0.00048216334 | H3: =SUM(CE3,CZ3,DU3,EP3,FK3,GF3,HA3,HV3,IQ3,JL3) -> 0.00048216334 | I3: =G3-H3 -> 0 | J3: =F3*(1+H3) -> 1.0004822 | K3: 1.0004822 | L3: =K3-J3 -> 0 | M3: 1.958 | N3: 1.967 | O3: =M3/$M$3 -> 1 | P3: =N3/$M$3 -> 1.0045965 | Q3: =IFERROR(N3/M3-1,0) -> 0.0045965271 | R3: =SUM(IF(BM3="lease",BU3,0),IF(CH3="lease",CP3,0),IF(DC3="lease",DK3,0),IF(DX3="lease",EF3,0),IF(ES3="lease",FA3,0),IF(FN3="lease",FV3,0),IF(GI3="lease",GQ3,0),IF(HD3="lease",HL3,0),IF(HY3="lease",IG3,0),IF(IT3="lease",JB3,0)) -> 1 | S3: =SUM(IF(BM3="lease",BV3,0),IF(CH3="lease",CQ3,0),IF(DC3="lease",DL3,0),IF(DX3="lease",EG3,0),IF(ES3="lease",FB3,0),IF(FN3="lease",FW3,0),IF(GI3="lease",GR3,0),IF(HD3="lease",HM3,0),IF(HY3="lease",IH3,0),IF(IT3="lease",JC3,0)) -> 1.0004822 | T3: =SUM(IF(BM3="keep",BU3,0),IF(CH3="keep",CP3,0),IF(DC3="keep",DK3,0),IF(DX3="keep",EF3,0),IF(ES3="keep",FA3,0),IF(FN3="keep",FV3,0),IF(GI3="keep",GQ3,0),IF(HD3="keep",HL3,0),IF(HY3="keep",IG3,0),IF(IT3="keep",JB3,0)) -> 0 | U3: =SUM(IF(BM3="keep",BV3,0),IF(CH3="keep",CQ3,0),IF(DC3="keep",DL3,0),IF(DX3="keep",EG3,0),IF(ES3="keep",FB3,0),IF(FN3="keep",FW3,0),IF(GI3="keep",GR3,0),IF(HD3="keep",HM3,0),IF(HY3="keep",IH3,0),IF(IT3="keep",JC3,0)) -> 0 | V3: =R3/O3 -> 1 | W3: =S3/P3 -> 0.99590446 | X3: =T3/O3 -> 0 | Y3: =U3/P3 -> 0 | Z3: =V3+X3 -> 1 | AA3: =IFERROR(W3/V3-1,0) -> -0.0040955385 | AB3: =IFERROR((W3-V3)/Z3,0) -> -0.0040955385 | AC3: =IFERROR(Y3/X3-1,0) -> 0 | AD3: =IFERROR((Y3-X3)/Z3,0) -> 0 | AE3: =AB3+AD3 -> -0.0040955385 | AF3: =(1+Q3)*(1+AE3)-1 -> 0.00048216334 | AG3: =G3-AF3 -> 5.2041704e-17 | AH3: =SUM(IF(BM3="lease",BW3,0),IF(CH3="lease",CR3,0),IF(DC3="lease",DM3,0),IF(DX3="lease",EH3,0),IF(ES3="lease",FC3,0),IF(FN3="lease",FX3,0),IF(GI3="lease",GS3,0),IF(HD3="lease",HN3,0),IF(HY3="lease",II3,0),IF(IT3="lease",JD3,0)) -> 0.00048216334 | AI3: =SUM(IF(BM3="keep",BW3,0),IF(CH3="keep",CR3,0),IF(DC3="keep",DM3,0),IF(DX3="keep",EH3,0),IF(ES3="keep",FC3,0),IF(FN3="keep",FX3,0),IF(GI3="keep",GS3,0),IF(HD3="keep",HN3,0),IF(HY3="keep",II3,0),IF(IT3="keep",JD3,0)) -> 0 | AJ3: =SUM(IF(BM3="lease",BX3,0),IF(CH3="lease",CS3,0),IF(DC3="lease",DN3,0),IF(DX3="lease",EI3,0),IF(ES3="lease",FD3,0),IF(FN3="lease",FY3,0),IF(GI3="lease",GT3,0),IF(HD3="lease",HO3,0),IF(HY3="lease",IJ3,0),IF(IT3="lease",JE3,0)) -> 0 | AK3: =SUM(IF(BM3="keep",BX3,0),IF(CH3="keep",CS3,0),IF(DC3="keep",DN3,0),IF(DX3="keep",EI3,0),IF(ES3="keep",FD3,0),IF(FN3="keep",FY3,0),IF(GI3="keep",GT3,0),IF(HD3="keep",HO3,0),IF(HY3="keep",IJ3,0),IF(IT3="keep",JE3,0)) -> 0 | AL3: =0 -> 0 | AM3: =0 -> 0 | AN3: =R3 -> 1 | AO3: =AH3 -> 0.00048216334 | AP3: =AL3 -> 0 | AQ3: =AN3+AO3+AP3 -> 1.0004822 | AR3: =S3-AQ3 -> 0 | AS3: =T3 -> 0 | AT3: =AI3 -> 0 | AU3: =AM3 -> 0 | AV3: =AS3+AT3+AU3 -> 0 | AW3: =U3-AV3 -> 0 | AX3: 1 | AY3: 1.0004822 | AZ3: =S3-AY3 -> 0 | BA3: 0 | BB3: 0 | BC3: =U3-BB3 -> 0 | BD3: =SUM(IF(BL3="direct",CE3,0),IF(CG3="direct",CZ3,0),IF(DB3="direct",DU3,0),IF(DW3="direct",EP3,0),IF(ER3="direct",FK3,0),IF(FM3="direct",GF3,0),IF(GH3="direct",HA3,0),IF(HC3="direct",HV3,0),IF(HX3="direct",IQ3,0),IF(IS3="direct",JL3,0)) -> 0.0024997145 | BE3: =SUM(IF(BL3="treasury",CE3,0),IF(CG3="treasury",CZ3,0),IF(DB3="treasury",DU3,0),IF(DW3="treasury",EP3,0),IF(ER3="treasury",FK3,0),IF(FM3="treasury",GF3,0),IF(GH3="treasury",HA3,0),IF(HC3="treasury",HV3,0),IF(HX3="treasury",IQ3,0),IF(IS3="treasury",JL3,0)) -> 7.6600564e-05 | BF3: =SUM(IF(BL3="future",CE3,0),IF(CG3="future",CZ3,0),IF(DB3="future",DU3,0),IF(DW3="future",EP3,0),IF(ER3="future",FK3,0),IF(FM3="future",GF3,0),IF(GH3="future",HA3,0),IF(HC3="future",HV3,0),IF(HX3="future",IQ3,0),IF(IS3="future",JL3,0)) -> -0.0020941517 | BG3: =SUM(IF(BL3="cash",CE3,0),IF(CG3="cash",CZ3,0),IF(DB3="cash",DU3,0),IF(DW3="cash",EP3,0),IF(ER3="cash",FK3,0),IF(FM3="cash",GF3,0),IF(GH3="cash",HA3,0),IF(HC3="cash",HV3,0),IF(HX3="cash",IQ3,0),IF(IS3="cash",JL3,0)) -> 0 | BH3: =SUM(BD3:BG3) -> 0.00048216334 | BI3: =G3-BH3 -> 0 | BJ3: =COUNTA(BK3,CF3,DA3,DV3,EQ3,FL3,GG3,HB3,HW3,IR3) -> 5 | BK3: Direct commodity holding | BL3: direct | BM3: lease | BN3: long | BP3: 1.958 | BQ3: 1.967 | BR3: 0.27816054 | BS3: 0.54463834 | BT3: 0.54463834 | BU3: 0.54463834 | BV3: 0.54714179 | BW3: 0.0024997145 | BX3: 3.7303996e-06 | BY3: 1.958 | BZ3: 1.967 | CE3: =IFERROR(BW3/F3,0) -> 0.0024997145 | CF3: Treasury collateral | CG3: treasury | CH3: lease | CI3: long | CK3: 100 | CL3: 100.01682 | CM3: 0.0045536166 | CN3: 0.45536166 | CO3: 0.45536166 | CP3: 0.45536166 | CQ3: 0.45543826 | CR3: 7.6600564e-05 | CS3: 7.727651e-17 | CT3: 1.958 | CU3: 1.967 | CY3: 27 | CZ3: =IFERROR(CR3/F3,0) -> 7.6600564e-05 | DA3: SI69F | DB3: future | DC3: lease | DD3: long | DE3: regular | DF3: 1.957 | DG3: 1.948 | DH3: 0.23268352 | DI3: 0.45536166 | DJ3: 0.45536166 | DK3: 0 | DL3: 0 | DM3: -0.0020941517 | DN3: 0.0020941517 | DO3: 1.958 | DP3: 1.967 | DQ3: -0.00051072523 | DR3: 0.0614 | DS3: 0.068304248 | DT3: 27 | DU3: =IFERROR(DM3/F3,0) -> -0.0020941517 | DV3: Lease cash / margin / financing | DW3: cash | DX3: lease | DY3: cash | EA3: 1 | EB3: 1 | EC3: 0 | EE3: 0 | EF3: 0 | EG3: -0.0020978821 | EH3: 0 | EI3: -0.0020978821 | EJ3: 1.958 | EK3: 1.967 | EP3: =IFERROR(EH3/F3,0) -> 0 | EQ3: Keep cash / margin / financing | ER3: cash | ES3: keep | ET3: cash | EV3: 1 | EW3: 1 | EX3: 0 | EZ3: 0 | FA3: 0 | FB3: 0 | FC3: 0 | FD3: 0 | FE3: 1.958 | FF3: 1.967 | FK3: =IFERROR(FC3/F3,0) -> 0
A4: 25206 | B4: 25209 | C4: =B4-A4 -> 3 | D4: 25206 | E4: positive | F4: 1.0004822 | G4: -0.0036029406 | H4: =SUM(CE4,CZ4,DU4,EP4,FK4,GF4,HA4,HV4,IQ4,JL4) -> -0.0036029406 | I4: =G4-H4 -> 4.3368087e-19 | J4: =F4*(1+H4) -> 0.99687749 | K4: 0.99687749 | L4: =K4-J4 -> 0 | M4: 1.967 | N4: 1.972 | O4: =M4/$M$3 -> 1.0045965 | P4: =N4/$M$3 -> 1.0071502 | Q4: =IFERROR(N4/M4-1,0) -> 0.002541942 | R4: =SUM(IF(BM4="lease",BU4,0),IF(CH4="lease",CP4,0),IF(DC4="lease",DK4,0),IF(DX4="lease",EF4,0),IF(ES4="lease",FA4,0),IF(FN4="lease",FV4,0),IF(GI4="lease",GQ4,0),IF(HD4="lease",HL4,0),IF(HY4="lease",IG4,0),IF(IT4="lease",JB4,0)) -> 1.0004822 | S4: =SUM(IF(BM4="lease",BV4,0),IF(CH4="lease",CQ4,0),IF(DC4="lease",DL4,0),IF(DX4="lease",EG4,0),IF(ES4="lease",FB4,0),IF(FN4="lease",FW4,0),IF(GI4="lease",GR4,0),IF(HD4="lease",HM4,0),IF(HY4="lease",IH4,0),IF(IT4="lease",JC4,0)) -> 0.99687749 | T4: =SUM(IF(BM4="keep",BU4,0),IF(CH4="keep",CP4,0),IF(DC4="keep",DK4,0),IF(DX4="keep",EF4,0),IF(ES4="keep",FA4,0),IF(FN4="keep",FV4,0),IF(GI4="keep",GQ4,0),IF(HD4="keep",HL4,0),IF(HY4="keep",IG4,0),IF(IT4="keep",JB4,0)) -> 0 | U4: =SUM(IF(BM4="keep",BV4,0),IF(CH4="keep",CQ4,0),IF(DC4="keep",DL4,0),IF(DX4="keep",EG4,0),IF(ES4="keep",FB4,0),IF(FN4="keep",FW4,0),IF(GI4="keep",GR4,0),IF(HD4="keep",HM4,0),IF(HY4="keep",IH4,0),IF(IT4="keep",JC4,0)) -> 0 | V4: =R4/O4 -> 0.99590446 | W4: =S4/P4 -> 0.98980026 | X4: =T4/O4 -> 0 | Y4: =U4/P4 -> 0 | Z4: =V4+X4 -> 0.99590446 | AA4: =IFERROR(W4/V4-1,0) -> -0.0061293023 | AB4: =IFERROR((W4-V4)/Z4,0) -> -0.0061293023 | AC4: =IFERROR(Y4/X4-1,0) -> 0 | AD4: =IFERROR((Y4-X4)/Z4,0) -> 0 | AE4: =AB4+AD4 -> -0.0061293023 | AF4: =(1+Q4)*(1+AE4)-1 -> -0.0036029406 | AG4: =G4-AF4 -> -5.2041704e-17 | AH4: =SUM(IF(BM4="lease",BW4,0),IF(CH4="lease",CR4,0),IF(DC4="lease",DM4,0),IF(DX4="lease",EH4,0),IF(ES4="lease",FC4,0),IF(FN4="lease",FX4,0),IF(GI4="lease",GS4,0),IF(HD4="lease",HN4,0),IF(HY4="lease",II4,0),IF(IT4="lease",JD4,0)) -> -0.0036046778 | AI4: =SUM(IF(BM4="keep",BW4,0),IF(CH4="keep",CR4,0),IF(DC4="keep",DM4,0),IF(DX4="keep",EH4,0),IF(ES4="keep",FC4,0),IF(FN4="keep",FX4,0),IF(GI4="keep",GS4,0),IF(HD4="keep",HN4,0),IF(HY4="keep",II4,0),IF(IT4="keep",JD4,0)) -> 0 | AJ4: =SUM(IF(BM4="lease",BX4,0),IF(CH4="lease",CS4,0),IF(DC4="lease",DN4,0),IF(DX4="lease",EI4,0),IF(ES4="lease",FD4,0),IF(FN4="lease",FY4,0),IF(GI4="lease",GT4,0),IF(HD4="lease",HO4,0),IF(HY4="lease",IJ4,0),IF(IT4="lease",JE4,0)) -> 0 | AK4: =SUM(IF(BM4="keep",BX4,0),IF(CH4="keep",CS4,0),IF(DC4="keep",DN4,0),IF(DX4="keep",EI4,0),IF(ES4="keep",FD4,0),IF(FN4="keep",FY4,0),IF(GI4="keep",GT4,0),IF(HD4="keep",HO4,0),IF(HY4="keep",IJ4,0),IF(IT4="keep",JE4,0)) -> 0 | AL4: =R4-S3 -> 0 | AM4: =T4-U3 -> 0 | AN4: =AN3 -> 1 | AO4: =AO3+AH4 -> -0.0031225144 | AP4: =AP3+AL4 -> 0 | AQ4: =AN4+AO4+AP4 -> 0.99687749 | AR4: =S4-AQ4 -> -1.110223e-16 | AS4: =AS3 -> 0 | AT4: =AT3+AI4 -> 0 | AU4: =AU3+AM4 -> 0 | AV4: =AS4+AT4+AU4 -> 0 | AW4: =U4-AV4 -> 0 | AX4: 1.0004822 | AY4: 0.99687749 | AZ4: =S4-AY4 -> 0 | BA4: 0 | BB4: 0 | BC4: =U4-BB4 -> 0 | BD4: =SUM(IF(BL4="direct",CE4,0),IF(CG4="direct",CZ4,0),IF(DB4="direct",DU4,0),IF(DW4="direct",EP4,0),IF(ER4="direct",FK4,0),IF(FM4="direct",GF4,0),IF(GH4="direct",HA4,0),IF(HC4="direct",HV4,0),IF(HX4="direct",IQ4,0),IF(IS4="direct",JL4,0)) -> 0 | BE4: =SUM(IF(BL4="treasury",CE4,0),IF(CG4="treasury",CZ4,0),IF(DB4="treasury",DU4,0),IF(DW4="treasury",EP4,0),IF(ER4="treasury",FK4,0),IF(FM4="treasury",GF4,0),IF(GH4="treasury",HA4,0),IF(HC4="treasury",HV4,0),IF(HX4="treasury",IQ4,0),IF(IS4="treasury",JL4,0)) -> 0.00050383562 | BF4: =SUM(IF(BL4="future",CE4,0),IF(CG4="future",CZ4,0),IF(DB4="future",DU4,0),IF(DW4="future",EP4,0),IF(ER4="future",FK4,0),IF(FM4="future",GF4,0),IF(GH4="future",HA4,0),IF(HC4="future",HV4,0),IF(HX4="future",IQ4,0),IF(IS4="future",JL4,0)) -> -0.0041067762 | BG4: =SUM(IF(BL4="cash",CE4,0),IF(CG4="cash",CZ4,0),IF(DB4="cash",DU4,0),IF(DW4="cash",EP4,0),IF(ER4="cash",FK4,0),IF(FM4="cash",GF4,0),IF(GH4="cash",HA4,0),IF(HC4="cash",HV4,0),IF(HX4="cash",IQ4,0),IF(IS4="cash",JL4,0)) -> 0 | BH4: =SUM(BD4:BG4) -> -0.0036029406 | BI4: =G4-BH4 -> 0 | BJ4: =COUNTA(BK4,CF4,DA4,DV4,EQ4,FL4,GG4,HB4,HW4,IR4) -> 4 | BK4: Treasury collateral | BL4: treasury | BM4: lease | BN4: long | BP4: 100.01682 | BQ4: 100.06721 | BR4: 0.010003139 | BS4: 1 | BT4: 1.0004822 | BU4: 1.0004822 | BV4: 1.0009862 | BW4: 0.00050407855 | BX4: 9.7795036e-17 | BY4: 1.967 | BZ4: 1.972 | CD4: 26 | CE4: =IFERROR(BW4/F4,0) -> 0.00050383562 | CF4: SI69F | CG4: future | CH4: lease | CI4: long | CJ4: regular | CK4: 1.948 | CL4: 1.94 | CM4: 0.51359454 | CN4: 1 | CO4: 1.0004822 | CP4: 0 | CQ4: 0 | CR4: -0.0041087563 | CS4: 0.0041087563 | CT4: 1.967 | CU4: 1.972 | CV4: -0.0096593798 | CW4: 0.0613 | CX4: 0.19690283 | CY4: 26 | CZ4: =IFERROR(CR4/F4,0) -> -0.0041067762 | DA4: Lease cash / margin / financing | DB4: cash | DC4: lease | DD4: cash | DF4: 1 | DG4: 1 | DH4: 0 | DJ4: 0 | DK4: 0 | DL4: -0.0041087563 | DM4: 0 | DN4: -0.0041087563 | DO4: 1.967 | DP4: 1.972 | DU4: =IFERROR(DM4/F4,0) -> 0 | DV4: Keep cash / margin / financing | DW4: cash | DX4: keep | DY4: cash | EA4: 1 | EB4: 1 | EC4: 0 | EE4: 0 | EF4: 0 | EG4: 0 | EH4: 0 | EI4: 0 | EJ4: 1.967 | EK4: 1.972 | EP4: =IFERROR(EH4/F4,0) -> 0
A5: 25209 | B5: 25210 | C5: =B5-A5 -> 1 | D5: 25209 | E5: positive | F5: 0.99687749 | G5: 0.0053239542 | H5: =SUM(CE5,CZ5,DU5,EP5,FK5,GF5,HA5,HV5,IQ5,JL5) -> 0.0053239542 | I5: =G5-H5 -> 0 | J5: =F5*(1+H5) -> 1.0021848 | K5: 1.0021848 | L5: =K5-J5 -> 0 | M5: 1.972 | N5: 1.977 | O5: =M5/$M$3 -> 1.0071502 | P5: =N5/$M$3 -> 1.0097038 | Q5: =IFERROR(N5/M5-1,0) -> 0.002535497 | R5: =SUM(IF(BM5="lease",BU5,0),IF(CH5="lease",CP5,0),IF(DC5="lease",DK5,0),IF(DX5="lease",EF5,0),IF(ES5="lease",FA5,0),IF(FN5="lease",FV5,0),IF(GI5="lease",GQ5,0),IF(HD5="lease",HL5,0),IF(HY5="lease",IG5,0),IF(IT5="lease",JB5,0)) -> 0.99687749 | S5: =SUM(IF(BM5="lease",BV5,0),IF(CH5="lease",CQ5,0),IF(DC5="lease",DL5,0),IF(DX5="lease",EG5,0),IF(ES5="lease",FB5,0),IF(FN5="lease",FW5,0),IF(GI5="lease",GR5,0),IF(HD5="lease",HM5,0),IF(HY5="lease",IH5,0),IF(IT5="lease",JC5,0)) -> 1.0021848 | T5: =SUM(IF(BM5="keep",BU5,0),IF(CH5="keep",CP5,0),IF(DC5="keep",DK5,0),IF(DX5="keep",EF5,0),IF(ES5="keep",FA5,0),IF(FN5="keep",FV5,0),IF(GI5="keep",GQ5,0),IF(HD5="keep",HL5,0),IF(HY5="keep",IG5,0),IF(IT5="keep",JB5,0)) -> 0 | U5: =SUM(IF(BM5="keep",BV5,0),IF(CH5="keep",CQ5,0),IF(DC5="keep",DL5,0),IF(DX5="keep",EG5,0),IF(ES5="keep",FB5,0),IF(FN5="keep",FW5,0),IF(GI5="keep",GR5,0),IF(HD5="keep",HM5,0),IF(HY5="keep",IH5,0),IF(IT5="keep",JC5,0)) -> 0 | V5: =R5/O5 -> 0.98980026 | W5: =S5/P5 -> 0.9925533 | X5: =T5/O5 -> 0 | Y5: =U5/P5 -> 0 | Z5: =V5+X5 -> 0.98980026 | AA5: =IFERROR(W5/V5-1,0) -> 0.002781405 | AB5: =IFERROR((W5-V5)/Z5,0) -> 0.002781405 | AC5: =IFERROR(Y5/X5-1,0) -> 0 | AD5: =IFERROR((Y5-X5)/Z5,0) -> 0 | AE5: =AB5+AD5 -> 0.002781405 | AF5: =(1+Q5)*(1+AE5)-1 -> 0.0053239542 | AG5: =G5-AF5 -> 2.1423835e-16 | AH5: =SUM(IF(BM5="lease",BW5,0),IF(CH5="lease",CR5,0),IF(DC5="lease",DM5,0),IF(DX5="lease",EH5,0),IF(ES5="lease",FC5,0),IF(FN5="lease",FX5,0),IF(GI5="lease",GS5,0),IF(HD5="lease",HN5,0),IF(HY5="lease",II5,0),IF(IT5="lease",JD5,0)) -> 0.0053073301 | AI5: =SUM(IF(BM5="keep",BW5,0),IF(CH5="keep",CR5,0),IF(DC5="keep",DM5,0),IF(DX5="keep",EH5,0),IF(ES5="keep",FC5,0),IF(FN5="keep",FX5,0),IF(GI5="keep",GS5,0),IF(HD5="keep",HN5,0),IF(HY5="keep",II5,0),IF(IT5="keep",JD5,0)) -> 0 | AJ5: =SUM(IF(BM5="lease",BX5,0),IF(CH5="lease",CS5,0),IF(DC5="lease",DN5,0),IF(DX5="lease",EI5,0),IF(ES5="lease",FD5,0),IF(FN5="lease",FY5,0),IF(GI5="lease",GT5,0),IF(HD5="lease",HO5,0),IF(HY5="lease",IJ5,0),IF(IT5="lease",JE5,0)) -> 0 | AK5: =SUM(IF(BM5="keep",BX5,0),IF(CH5="keep",CS5,0),IF(DC5="keep",DN5,0),IF(DX5="keep",EI5,0),IF(ES5="keep",FD5,0),IF(FN5="keep",FY5,0),IF(GI5="keep",GT5,0),IF(HD5="keep",HO5,0),IF(HY5="keep",IJ5,0),IF(IT5="keep",JE5,0)) -> 0 | AL5: =R5-S4 -> 0 | AM5: =T5-U4 -> 0 | AN5: =AN4 -> 1 | AO5: =AO4+AH5 -> 0.0021848157 | AP5: =AP4+AL5 -> 0 | AQ5: =AN5+AO5+AP5 -> 1.0021848 | AR5: =S5-AQ5 -> 0 | AS5: =AS4 -> 0 | AT5: =AT4+AI5 -> 0 | AU5: =AU4+AM5 -> 0 | AV5: =AS5+AT5+AU5 -> 0 | AW5: =U5-AV5 -> 0 | AX5: 0.99687749 | AY5: 1.0021848 | AZ5: =S5-AY5 -> 0 | BA5: 0 | BB5: 0 | BC5: =U5-BB5 -> 0 | BD5: =SUM(IF(BL5="direct",CE5,0),IF(CG5="direct",CZ5,0),IF(DB5="direct",DU5,0),IF(DW5="direct",EP5,0),IF(ER5="direct",FK5,0),IF(FM5="direct",GF5,0),IF(GH5="direct",HA5,0),IF(HC5="direct",HV5,0),IF(HX5="direct",IQ5,0),IF(IS5="direct",JL5,0)) -> 0 | BE5: =SUM(IF(BL5="treasury",CE5,0),IF(CG5="treasury",CZ5,0),IF(DB5="treasury",DU5,0),IF(DW5="treasury",EP5,0),IF(ER5="treasury",FK5,0),IF(FM5="treasury",GF5,0),IF(GH5="treasury",HA5,0),IF(HC5="treasury",HV5,0),IF(HX5="treasury",IQ5,0),IF(IS5="treasury",JL5,0)) -> 0.00016931507 | BF5: =SUM(IF(BL5="future",CE5,0),IF(CG5="future",CZ5,0),IF(DB5="future",DU5,0),IF(DW5="future",EP5,0),IF(ER5="future",FK5,0),IF(FM5="future",GF5,0),IF(GH5="future",HA5,0),IF(HC5="future",HV5,0),IF(HX5="future",IQ5,0),IF(IS5="future",JL5,0)) -> 0.0051546392 | BG5: =SUM(IF(BL5="cash",CE5,0),IF(CG5="cash",CZ5,0),IF(DB5="cash",DU5,0),IF(DW5="cash",EP5,0),IF(ER5="cash",FK5,0),IF(FM5="cash",GF5,0),IF(GH5="cash",HA5,0),IF(HC5="cash",HV5,0),IF(HX5="cash",IQ5,0),IF(IS5="cash",JL5,0)) -> 0 | BH5: =SUM(BD5:BG5) -> 0.0053239542 | BI5: =G5-BH5 -> 0 | BJ5: =COUNTA(BK5,CF5,DA5,DV5,EQ5,FL5,GG5,HB5,HW5,IR5) -> 4 | BK5: Treasury collateral | BL5: treasury | BM5: lease | BN5: long | BP5: 100.06721 | BQ5: 100.08416 | BR5: 0.0099620789 | BS5: 1 | BT5: 0.99687749 | BU5: 0.99687749 | BV5: 0.99704627 | BW5: 0.00016878638 | BX5: 4.5617806e-17 | BY5: 1.972 | BZ5: 1.977 | CD5: 23 | CE5: =IFERROR(BW5/F5,0) -> 0.00016931507 | CF5: SI69F | CG5: future | CH5: lease | CI5: long | CJ5: regular | CK5: 1.94 | CL5: 1.95 | CM5: 0.51385437 | CN5: 1 | CO5: 0.99687749 | CP5: 0 | CQ5: 0 | CR5: 0.0051385437 | CS5: -0.0051385437 | CT5: 1.972 | CU5: 1.977 | CV5: -0.016227181 | CW5: 0.0618 | CX5: 0.3193183 | CY5: 23 | CZ5: =IFERROR(CR5/F5,0) -> 0.0051546392 | DA5: Lease cash / margin / financing | DB5: cash | DC5: lease | DD5: cash | DF5: 1 | DG5: 1 | DH5: -1.110223e-16 | DJ5: -1.110223e-16 | DK5: -1.110223e-16 | DL5: 0.0051385437 | DM5: 0 | DN5: 0.0051385437 | DO5: 1.972 | DP5: 1.977 | DU5: =IFERROR(DM5/F5,0) -> 0 | DV5: Keep cash / margin / financing | DW5: cash | DX5: keep | DY5: cash | EA5: 1 | EB5: 1 | EC5: 0 | EE5: 0 | EF5: 0 | EG5: 0 | EH5: 0 | EI5: 0 | EJ5: 1.972 | EK5: 1.977 | EP5: =IFERROR(EH5/F5,0) -> 0
A6: 25210 | B6: 25211 | C6: =B6-A6 -> 1 | D6: 25210 | E6: positive | F6: 1.0021848 | G6: 0.018119951 | H6: =SUM(CE6,CZ6,DU6,EP6,FK6,GF6,HA6,HV6,IQ6,JL6) -> 0.018119951 | I6: =G6-H6 -> 0 | J6: =F6*(1+H6) -> 1.0203444 | K6: 1.0203444 | L6: =K6-J6 -> 0 | M6: 1.977 | N6: 2.017 | O6: =M6/$M$3 -> 1.0097038 | P6: =N6/$M$3 -> 1.0301328 | Q6: =IFERROR(N6/M6-1,0) -> 0.020232676 | R6: =SUM(IF(BM6="lease",BU6,0),IF(CH6="lease",CP6,0),IF(DC6="lease",DK6,0),IF(DX6="lease",EF6,0),IF(ES6="lease",FA6,0),IF(FN6="lease",FV6,0),IF(GI6="lease",GQ6,0),IF(HD6="lease",HL6,0),IF(HY6="lease",IG6,0),IF(IT6="lease",JB6,0)) -> 1.0021848 | S6: =SUM(IF(BM6="lease",BV6,0),IF(CH6="lease",CQ6,0),IF(DC6="lease",DL6,0),IF(DX6="lease",EG6,0),IF(ES6="lease",FB6,0),IF(FN6="lease",FW6,0),IF(GI6="lease",GR6,0),IF(HD6="lease",HM6,0),IF(HY6="lease",IH6,0),IF(IT6="lease",JC6,0)) -> 1.0203444 | T6: =SUM(IF(BM6="keep",BU6,0),IF(CH6="keep",CP6,0),IF(DC6="keep",DK6,0),IF(DX6="keep",EF6,0),IF(ES6="keep",FA6,0),IF(FN6="keep",FV6,0),IF(GI6="keep",GQ6,0),IF(HD6="keep",HL6,0),IF(HY6="keep",IG6,0),IF(IT6="keep",JB6,0)) -> 0 | U6: =SUM(IF(BM6="keep",BV6,0),IF(CH6="keep",CQ6,0),IF(DC6="keep",DL6,0),IF(DX6="keep",EG6,0),IF(ES6="keep",FB6,0),IF(FN6="keep",FW6,0),IF(GI6="keep",GR6,0),IF(HD6="keep",HM6,0),IF(HY6="keep",IH6,0),IF(IT6="keep",JC6,0)) -> 0 | V6: =R6/O6 -> 0.9925533 | W6: =S6/P6 -> 0.99049789 | X6: =T6/O6 -> 0 | Y6: =U6/P6 -> 0 | Z6: =V6+X6 -> 0.9925533 | AA6: =IFERROR(W6/V6-1,0) -> -0.0020708266 | AB6: =IFERROR((W6-V6)/Z6,0) -> -0.0020708266 | AC6: =IFERROR(Y6/X6-1,0) -> 0 | AD6: =IFERROR((Y6-X6)/Z6,0) -> 0 | AE6: =AB6+AD6 -> -0.0020708266 | AF6: =(1+Q6)*(1+AE6)-1 -> 0.018119951 | AG6: =G6-AF6 -> 4.8572257e-17 | AH6: =SUM(IF(BM6="lease",BW6,0),IF(CH6="lease",CR6,0),IF(DC6="lease",DM6,0),IF(DX6="lease",EH6,0),IF(ES6="lease",FC6,0),IF(FN6="lease",FX6,0),IF(GI6="lease",GS6,0),IF(HD6="lease",HN6,0),IF(HY6="lease",II6,0),IF(IT6="lease",JD6,0)) -> 0.01815954 | AI6: =SUM(IF(BM6="keep",BW6,0),IF(CH6="keep",CR6,0),IF(DC6="keep",DM6,0),IF(DX6="keep",EH6,0),IF(ES6="keep",FC6,0),IF(FN6="keep",FX6,0),IF(GI6="keep",GS6,0),IF(HD6="keep",HN6,0),IF(HY6="keep",II6,0),IF(IT6="keep",JD6,0)) -> 0 | AJ6: =SUM(IF(BM6="lease",BX6,0),IF(CH6="lease",CS6,0),IF(DC6="lease",DN6,0),IF(DX6="lease",EI6,0),IF(ES6="lease",FD6,0),IF(FN6="lease",FY6,0),IF(GI6="lease",GT6,0),IF(HD6="lease",HO6,0),IF(HY6="lease",IJ6,0),IF(IT6="lease",JE6,0)) -> 0 | AK6: =SUM(IF(BM6="keep",BX6,0),IF(CH6="keep",CS6,0),IF(DC6="keep",DN6,0),IF(DX6="keep",EI6,0),IF(ES6="keep",FD6,0),IF(FN6="keep",FY6,0),IF(GI6="keep",GT6,0),IF(HD6="keep",HO6,0),IF(HY6="keep",IJ6,0),IF(IT6="keep",JE6,0)) -> 0 | AL6: =R6-S5 -> 0 | AM6: =T6-U5 -> 0 | AN6: =AN5 -> 1 | AO6: =AO5+AH6 -> 0.020344355 | AP6: =AP5+AL6 -> 0 | AQ6: =AN6+AO6+AP6 -> 1.0203444 | AR6: =S6-AQ6 -> 0 | AS6: =AS5 -> 0 | AT6: =AT5+AI6 -> 0 | AU6: =AU5+AM6 -> 0 | AV6: =AS6+AT6+AU6 -> 0 | AW6: =U6-AV6 -> 0 | AX6: 1.0021848 | AY6: 1.0203444 | AZ6: =S6-AY6 -> 0 | BA6: 0 | BB6: 0 | BC6: =U6-BB6 -> 0 | BD6: =SUM(IF(BL6="direct",CE6,0),IF(CG6="direct",CZ6,0),IF(DB6="direct",DU6,0),IF(DW6="direct",EP6,0),IF(ER6="direct",FK6,0),IF(FM6="direct",GF6,0),IF(GH6="direct",HA6,0),IF(HC6="direct",HV6,0),IF(HX6="direct",IQ6,0),IF(IS6="direct",JL6,0)) -> 0 | BE6: =SUM(IF(BL6="treasury",CE6,0),IF(CG6="treasury",CZ6,0),IF(DB6="treasury",DU6,0),IF(DW6="treasury",EP6,0),IF(ER6="treasury",FK6,0),IF(FM6="treasury",GF6,0),IF(GH6="treasury",HA6,0),IF(HC6="treasury",HV6,0),IF(HX6="treasury",IQ6,0),IF(IS6="treasury",JL6,0)) -> 0.00017123288 | BF6: =SUM(IF(BL6="future",CE6,0),IF(CG6="future",CZ6,0),IF(DB6="future",DU6,0),IF(DW6="future",EP6,0),IF(ER6="future",FK6,0),IF(FM6="future",GF6,0),IF(GH6="future",HA6,0),IF(HC6="future",HV6,0),IF(HX6="future",IQ6,0),IF(IS6="future",JL6,0)) -> 0.017948718 | BG6: =SUM(IF(BL6="cash",CE6,0),IF(CG6="cash",CZ6,0),IF(DB6="cash",DU6,0),IF(DW6="cash",EP6,0),IF(ER6="cash",FK6,0),IF(FM6="cash",GF6,0),IF(GH6="cash",HA6,0),IF(HC6="cash",HV6,0),IF(HX6="cash",IQ6,0),IF(IS6="cash",JL6,0)) -> 0 | BH6: =SUM(BD6:BG6) -> 0.018119951 | BI6: =G6-BH6 -> 0 | BJ6: =COUNTA(BK6,CF6,DA6,DV6,EQ6,FL6,GG6,HB6,HW6,IR6) -> 4 | BK6: Treasury collateral | BL6: treasury | BM6: lease | BN6: long | BP6: 100.08416 | BQ6: 100.10129 | BR6: 0.010013421 | BS6: 1 | BT6: 1.0021848 | BU6: 1.0021848 | BV6: 1.0023564 | BW6: 0.00017160699 | BX6: -7.3508907e-17 | BY6: 1.977 | BZ6: 2.017 | CD6: 22 | CE6: =IFERROR(BW6/F6,0) -> 0.00017123288 | CF6: SI69F | CG6: future | CH6: lease | CI6: long | CJ6: regular | CK6: 1.95 | CL6: 1.985 | CM6: 0.51394093 | CN6: 1 | CO6: 1.0021848 | CP6: 0 | CQ6: 0 | CR6: 0.017987933 | CS6: -0.017987933 | CT6: 1.977 | CU6: 2.017 | CV6: -0.013657056 | CW6: 0.0625 | CX6: 0.28908298 | CY6: 22 | CZ6: =IFERROR(CR6/F6,0) -> 0.017948718 | DA6: Lease cash / margin / financing | DB6: cash | DC6: lease | DD6: cash | DF6: 1 | DG6: 1 | DH6: 0 | DJ6: 0 | DK6: 0 | DL6: 0.017987933 | DM6: 0 | DN6: 0.017987933 | DO6: 1.977 | DP6: 2.017 | DU6: =IFERROR(DM6/F6,0) -> 0 | DV6: Keep cash / margin / financing | DW6: cash | DX6: keep | DY6: cash | EA6: 1 | EB6: 1 | EC6: 0 | EE6: 0 | EF6: 0 | EG6: 0 | EH6: 0 | EI6: 0 | EJ6: 1.977 | EK6: 2.017 | EP6: =IFERROR(EH6/F6,0) -> 0
A7: 25211 | B7: 25212 | C7: =B7-A7 -> 1 | D7: 25211 | E7: positive | F7: 1.0203444 | G7: 0.021328279 | H7: =SUM(CE7,CZ7,DU7,EP7,FK7,GF7,HA7,HV7,IQ7,JL7) -> 0.021328279 | I7: =G7-H7 -> 0 | J7: =F7*(1+H7) -> 1.0421065 | K7: 1.0421065 | L7: =K7-J7 -> 0 | M7: 2.017 | N7: 2.007 | O7: =M7/$M$3 -> 1.0301328 | P7: =N7/$M$3 -> 1.0250255 | Q7: =IFERROR(N7/M7-1,0) -> -0.0049578582 | R7: =SUM(IF(BM7="lease",BU7,0),IF(CH7="lease",CP7,0),IF(DC7="lease",DK7,0),IF(DX7="lease",EF7,0),IF(ES7="lease",FA7,0),IF(FN7="lease",FV7,0),IF(GI7="lease",GQ7,0),IF(HD7="lease",HL7,0),IF(HY7="lease",IG7,0),IF(IT7="lease",JB7,0)) -> 1.0203444 | S7: =SUM(IF(BM7="lease",BV7,0),IF(CH7="lease",CQ7,0),IF(DC7="lease",DL7,0),IF(DX7="lease",EG7,0),IF(ES7="lease",FB7,0),IF(FN7="lease",FW7,0),IF(GI7="lease",GR7,0),IF(HD7="lease",HM7,0),IF(HY7="lease",IH7,0),IF(IT7="lease",JC7,0)) -> 1.0421065 | T7: =SUM(IF(BM7="keep",BU7,0),IF(CH7="keep",CP7,0),IF(DC7="keep",DK7,0),IF(DX7="keep",EF7,0),IF(ES7="keep",FA7,0),IF(FN7="keep",FV7,0),IF(GI7="keep",GQ7,0),IF(HD7="keep",HL7,0),IF(HY7="keep",IG7,0),IF(IT7="keep",JB7,0)) -> 0 | U7: =SUM(IF(BM7="keep",BV7,0),IF(CH7="keep",CQ7,0),IF(DC7="keep",DL7,0),IF(DX7="keep",EG7,0),IF(ES7="keep",FB7,0),IF(FN7="keep",FW7,0),IF(GI7="keep",GR7,0),IF(HD7="keep",HM7,0),IF(HY7="keep",IH7,0),IF(IT7="keep",JC7,0)) -> 0 | V7: =R7/O7 -> 0.99049789 | W7: =S7/P7 -> 1.016664 | X7: =T7/O7 -> 0 | Y7: =U7/P7 -> 0 | Z7: =V7+X7 -> 0.99049789 | AA7: =IFERROR(W7/V7-1,0) -> 0.02641711 | AB7: =IFERROR((W7-V7)/Z7,0) -> 0.02641711 | AC7: =IFERROR(Y7/X7-1,0) -> 0 | AD7: =IFERROR((Y7-X7)/Z7,0) -> 0 | AE7: =AB7+AD7 -> 0.02641711 | AF7: =(1+Q7)*(1+AE7)-1 -> 0.021328279 | AG7: =G7-AF7 -> -3.1571967e-16 | AH7: =SUM(IF(BM7="lease",BW7,0),IF(CH7="lease",CR7,0),IF(DC7="lease",DM7,0),IF(DX7="lease",EH7,0),IF(ES7="lease",FC7,0),IF(FN7="lease",FX7,0),IF(GI7="lease",GS7,0),IF(HD7="lease",HN7,0),IF(HY7="lease",II7,0),IF(IT7="lease",JD7,0)) -> 0.021762189 | AI7: =SUM(IF(BM7="keep",BW7,0),IF(CH7="keep",CR7,0),IF(DC7="keep",DM7,0),IF(DX7="keep",EH7,0),IF(ES7="keep",FC7,0),IF(FN7="keep",FX7,0),IF(GI7="keep",GS7,0),IF(HD7="keep",HN7,0),IF(HY7="keep",II7,0),IF(IT7="keep",JD7,0)) -> 0 | AJ7: =SUM(IF(BM7="lease",BX7,0),IF(CH7="lease",CS7,0),IF(DC7="lease",DN7,0),IF(DX7="lease",EI7,0),IF(ES7="lease",FD7,0),IF(FN7="lease",FY7,0),IF(GI7="lease",GT7,0),IF(HD7="lease",HO7,0),IF(HY7="lease",IJ7,0),IF(IT7="lease",JE7,0)) -> 0 | AK7: =SUM(IF(BM7="keep",BX7,0),IF(CH7="keep",CS7,0),IF(DC7="keep",DN7,0),IF(DX7="keep",EI7,0),IF(ES7="keep",FD7,0),IF(FN7="keep",FY7,0),IF(GI7="keep",GT7,0),IF(HD7="keep",HO7,0),IF(HY7="keep",IJ7,0),IF(IT7="keep",JE7,0)) -> 0 | AL7: =R7-S6 -> 0 | AM7: =T7-U6 -> 0 | AN7: =AN6 -> 1 | AO7: =AO6+AH7 -> 0.042106545 | AP7: =AP6+AL7 -> 0 | AQ7: =AN7+AO7+AP7 -> 1.0421065 | AR7: =S7-AQ7 -> 0 | AS7: =AS6 -> 0 | AT7: =AT6+AI7 -> 0 | AU7: =AU6+AM7 -> 0 | AV7: =AS7+AT7+AU7 -> 0 | AW7: =U7-AV7 -> 0 | AX7: 1.0203444 | AY7: 1.0421065 | AZ7: =S7-AY7 -> 0 | BA7: 0 | BB7: 0 | BC7: =U7-BB7 -> 0 | BD7: =SUM(IF(BL7="direct",CE7,0),IF(CG7="direct",CZ7,0),IF(DB7="direct",DU7,0),IF(DW7="direct",EP7,0),IF(ER7="direct",FK7,0),IF(FM7="direct",GF7,0),IF(GH7="direct",HA7,0),IF(HC7="direct",HV7,0),IF(HX7="direct",IQ7,0),IF(IS7="direct",JL7,0)) -> 0 | BE7: =SUM(IF(BL7="treasury",CE7,0),IF(CG7="treasury",CZ7,0),IF(DB7="treasury",DU7,0),IF(DW7="treasury",EP7,0),IF(ER7="treasury",FK7,0),IF(FM7="treasury",GF7,0),IF(GH7="treasury",HA7,0),IF(HC7="treasury",HV7,0),IF(HX7="treasury",IQ7,0),IF(IS7="treasury",JL7,0)) -> 0.00016958904 | BF7: =SUM(IF(BL7="future",CE7,0),IF(CG7="future",CZ7,0),IF(DB7="future",DU7,0),IF(DW7="future",EP7,0),IF(ER7="future",FK7,0),IF(FM7="future",GF7,0),IF(GH7="future",HA7,0),IF(HC7="future",HV7,0),IF(HX7="future",IQ7,0),IF(IS7="future",JL7,0)) -> 0.02115869 | BG7: =SUM(IF(BL7="cash",CE7,0),IF(CG7="cash",CZ7,0),IF(DB7="cash",DU7,0),IF(DW7="cash",EP7,0),IF(ER7="cash",FK7,0),IF(FM7="cash",GF7,0),IF(GH7="cash",HA7,0),IF(HC7="cash",HV7,0),IF(HX7="cash",IQ7,0),IF(IS7="cash",JL7,0)) -> 0 | BH7: =SUM(BD7:BG7) -> 0.021328279 | BI7: =G7-BH7 -> 0 | BJ7: =COUNTA(BK7,CF7,DA7,DV7,EQ7,FL7,GG7,HB7,HW7,IR7) -> 4 | BK7: Treasury collateral | BL7: treasury | BM7: lease | BN7: long | BP7: 100.10129 | BQ7: 100.11827 | BR7: 0.010193118 | BS7: 1 | BT7: 1.0203444 | BU7: 1.0203444 | BV7: 1.0205174 | BW7: 0.00017303922 | BX7: 2.0841076e-16 | BY7: 2.017 | BZ7: 2.007 | CD7: 21 | CE7: =IFERROR(BW7/F7,0) -> 0.00016958904 | CF7: SI69F | CG7: future | CH7: lease | CI7: long | CJ7: regular | CK7: 1.985 | CL7: 2.027 | CM7: 0.51402738 | CN7: 1 | CO7: 1.0203444 | CP7: 0 | CQ7: 0 | CR7: 0.02158915 | CS7: -0.02158915 | CT7: 2.017 | CU7: 2.007 | CV7: -0.015865146 | CW7: 0.0619 | CX7: 0.33765135 | CY7: 21 | CZ7: =IFERROR(CR7/F7,0) -> 0.02115869 | DA7: Lease cash / margin / financing | DB7: cash | DC7: lease | DD7: cash | DF7: 1 | DG7: 1 | DH7: 0 | DJ7: 0 | DK7: 0 | DL7: 0.02158915 | DM7: 0 | DN7: 0.02158915 | DO7: 2.017 | DP7: 2.007 | DU7: =IFERROR(DM7/F7,0) -> 0 | DV7: Keep cash / margin / financing | DW7: cash | DX7: keep | DY7: cash | EA7: 1 | EB7: 1 | EC7: 0 | EE7: 0 | EF7: 0 | EG7: 0 | EH7: 0 | EI7: 0 | EJ7: 2.017 | EK7: 2.007 | EP7: =IFERROR(EH7/F7,0) -> 0
A8: 25212 | B8: 25213 | C8: =B8-A8 -> 1 | D8: 25212 | E8: neutral | F8: 1.0421065 | G8: 0.017432114 | H8: =SUM(CE8,CZ8,DU8,EP8,FK8,GF8,HA8,HV8,IQ8,JL8) -> 0.017432114 | I8: =G8-H8 -> 0 | J8: =F8*(1+H8) -> 1.0602727 | K8: 1.0602727 | L8: =K8-J8 -> 0 | M8: 2.007 | N8: 2.042 | O8: =M8/$M$3 -> 1.0250255 | P8: =N8/$M$3 -> 1.0429009 | Q8: =IFERROR(N8/M8-1,0) -> 0.017438964 | R8: =SUM(IF(BM8="lease",BU8,0),IF(CH8="lease",CP8,0),IF(DC8="lease",DK8,0),IF(DX8="lease",EF8,0),IF(ES8="lease",FA8,0),IF(FN8="lease",FV8,0),IF(GI8="lease",GQ8,0),IF(HD8="lease",HL8,0),IF(HY8="lease",IG8,0),IF(IT8="lease",JB8,0)) -> 1.0421065 | S8: =SUM(IF(BM8="lease",BV8,0),IF(CH8="lease",CQ8,0),IF(DC8="lease",DL8,0),IF(DX8="lease",EG8,0),IF(ES8="lease",FB8,0),IF(FN8="lease",FW8,0),IF(GI8="lease",GR8,0),IF(HD8="lease",HM8,0),IF(HY8="lease",IH8,0),IF(IT8="lease",JC8,0)) -> 1.0602727 | T8: =SUM(IF(BM8="keep",BU8,0),IF(CH8="keep",CP8,0),IF(DC8="keep",DK8,0),IF(DX8="keep",EF8,0),IF(ES8="keep",FA8,0),IF(FN8="keep",FV8,0),IF(GI8="keep",GQ8,0),IF(HD8="keep",HL8,0),IF(HY8="keep",IG8,0),IF(IT8="keep",JB8,0)) -> 0 | U8: =SUM(IF(BM8="keep",BV8,0),IF(CH8="keep",CQ8,0),IF(DC8="keep",DL8,0),IF(DX8="keep",EG8,0),IF(ES8="keep",FB8,0),IF(FN8="keep",FW8,0),IF(GI8="keep",GR8,0),IF(HD8="keep",HM8,0),IF(HY8="keep",IH8,0),IF(IT8="keep",JC8,0)) -> 0 | V8: =R8/O8 -> 1.016664 | W8: =S8/P8 -> 1.0166571 | X8: =T8/O8 -> 0 | Y8: =U8/P8 -> 0 | Z8: =V8+X8 -> 1.016664 | AA8: =IFERROR(W8/V8-1,0) -> -6.7319174e-06 | AB8: =IFERROR((W8-V8)/Z8,0) -> -6.7319174e-06 | AC8: =IFERROR(Y8/X8-1,0) -> 0 | AD8: =IFERROR((Y8-X8)/Z8,0) -> 0 | AE8: =AB8+AD8 -> -6.7319174e-06 | AF8: =(1+Q8)*(1+AE8)-1 -> 0.017432114 | AG8: =G8-AF8 -> -4.510281e-17 | AH8: =SUM(IF(BM8="lease",BW8,0),IF(CH8="lease",CR8,0),IF(DC8="lease",DM8,0),IF(DX8="lease",EH8,0),IF(ES8="lease",FC8,0),IF(FN8="lease",FX8,0),IF(GI8="lease",GS8,0),IF(HD8="lease",HN8,0),IF(HY8="lease",II8,0),IF(IT8="lease",JD8,0)) -> 0.01816612 | AI8: =SUM(IF(BM8="keep",BW8,0),IF(CH8="keep",CR8,0),IF(DC8="keep",DM8,0),IF(DX8="keep",EH8,0),IF(ES8="keep",FC8,0),IF(FN8="keep",FX8,0),IF(GI8="keep",GS8,0),IF(HD8="keep",HN8,0),IF(HY8="keep",II8,0),IF(IT8="keep",JD8,0)) -> 0 | AJ8: =SUM(IF(BM8="lease",BX8,0),IF(CH8="lease",CS8,0),IF(DC8="lease",DN8,0),IF(DX8="lease",EI8,0),IF(ES8="lease",FD8,0),IF(FN8="lease",FY8,0),IF(GI8="lease",GT8,0),IF(HD8="lease",HO8,0),IF(HY8="lease",IJ8,0),IF(IT8="lease",JE8,0)) -> 0 | AK8: =SUM(IF(BM8="keep",BX8,0),IF(CH8="keep",CS8,0),IF(DC8="keep",DN8,0),IF(DX8="keep",EI8,0),IF(ES8="keep",FD8,0),IF(FN8="keep",FY8,0),IF(GI8="keep",GT8,0),IF(HD8="keep",HO8,0),IF(HY8="keep",IJ8,0),IF(IT8="keep",JE8,0)) -> 0 | AL8: =R8-S7 -> 0 | AM8: =T8-U7 -> 0 | AN8: =AN7 -> 1 | AO8: =AO7+AH8 -> 0.060272665 | AP8: =AP7+AL8 -> 0 | AQ8: =AN8+AO8+AP8 -> 1.0602727 | AR8: =S8-AQ8 -> 0 | AS8: =AS7 -> 0 | AT8: =AT7+AI8 -> 0 | AU8: =AU7+AM8 -> 0 | AV8: =AS8+AT8+AU8 -> 0 | AW8: =U8-AV8 -> 0 | AX8: 1.0421065 | AY8: 1.0602727 | AZ8: =S8-AY8 -> 0 | BA8: 0 | BB8: 0 | BC8: =U8-BB8 -> 0 | BD8: =SUM(IF(BL8="direct",CE8,0),IF(CG8="direct",CZ8,0),IF(DB8="direct",DU8,0),IF(DW8="direct",EP8,0),IF(ER8="direct",FK8,0),IF(FM8="direct",GF8,0),IF(GH8="direct",HA8,0),IF(HC8="direct",HV8,0),IF(HX8="direct",IQ8,0),IF(IS8="direct",JL8,0)) -> 0.017432114 | BE8: =SUM(IF(BL8="treasury",CE8,0),IF(CG8="treasury",CZ8,0),IF(DB8="treasury",DU8,0),IF(DW8="treasury",EP8,0),IF(ER8="treasury",FK8,0),IF(FM8="treasury",GF8,0),IF(GH8="treasury",HA8,0),IF(HC8="treasury",HV8,0),IF(HX8="treasury",IQ8,0),IF(IS8="treasury",JL8,0)) -> 0 | BF8: =SUM(IF(BL8="future",CE8,0),IF(CG8="future",CZ8,0),IF(DB8="future",DU8,0),IF(DW8="future",EP8,0),IF(ER8="future",FK8,0),IF(FM8="future",GF8,0),IF(GH8="future",HA8,0),IF(HC8="future",HV8,0),IF(HX8="future",IQ8,0),IF(IS8="future",JL8,0)) -> 0 | BG8: =SUM(IF(BL8="cash",CE8,0),IF(CG8="cash",CZ8,0),IF(DB8="cash",DU8,0),IF(DW8="cash",EP8,0),IF(ER8="cash",FK8,0),IF(FM8="cash",GF8,0),IF(GH8="cash",HA8,0),IF(HC8="cash",HV8,0),IF(HX8="cash",IQ8,0),IF(IS8="cash",JL8,0)) -> 0 | BH8: =SUM(BD8:BG8) -> 0.017432114 | BI8: =G8-BH8 -> 0 | BJ8: =COUNTA(BK8,CF8,DA8,DV8,EQ8,FL8,GG8,HB8,HW8,IR8) -> 3 | BK8: Direct commodity holding | BL8: direct | BM8: lease | BN8: long | BP8: 2.007 | BQ8: 2.042 | BR8: 0.51923595 | BS8: 1 | BT8: 1.0421065 | BU8: 1.0421065 | BV8: 1.0602798 | BW8: 0.01816612 | BX8: 7.1377161e-06 | BY8: 2.007 | BZ8: 2.042 | CE8: =IFERROR(BW8/F8,0) -> 0.017432114 | CF8: Lease cash / margin / financing | CG8: cash | CH8: lease | CI8: cash | CK8: 1 | CL8: 1 | CM8: 0 | CO8: 0 | CP8: 0 | CQ8: -7.1377161e-06 | CR8: 0 | CS8: -7.1377161e-06 | CT8: 2.007 | CU8: 2.042 | CZ8: =IFERROR(CR8/F8,0) -> 0 | DA8: Keep cash / margin / financing | DB8: cash | DC8: keep | DD8: cash | DF8: 1 | DG8: 1 | DH8: 0 | DJ8: 0 | DK8: 0 | DL8: 0 | DM8: 0 | DN8: 0 | DO8: 2.007 | DP8: 2.042 | DU8: =IFERROR(DM8/F8,0) -> 0
A9: 25213 | B9: 25216 | C9: =B9-A9 -> 3 | D9: 25213 | E9: positive | F9: 1.0602727 | G9: -0.0019978082 | H9: =SUM(CE9,CZ9,DU9,EP9,FK9,GF9,HA9,HV9,IQ9,JL9) -> -0.0019978082 | I9: =G9-H9 -> -4.3368087e-19 | J9: =F9*(1+H9) -> 1.0581544 | K9: 1.0581544 | L9: =K9-J9 -> 0 | M9: 2.042 | N9: 2.016 | O9: =M9/$M$3 -> 1.0429009 | P9: =N9/$M$3 -> 1.0296221 | Q9: =IFERROR(N9/M9-1,0) -> -0.012732615 | R9: =SUM(IF(BM9="lease",BU9,0),IF(CH9="lease",CP9,0),IF(DC9="lease",DK9,0),IF(DX9="lease",EF9,0),IF(ES9="lease",FA9,0),IF(FN9="lease",FV9,0),IF(GI9="lease",GQ9,0),IF(HD9="lease",HL9,0),IF(HY9="lease",IG9,0),IF(IT9="lease",JB9,0)) -> 1.0602727 | S9: =SUM(IF(BM9="lease",BV9,0),IF(CH9="lease",CQ9,0),IF(DC9="lease",DL9,0),IF(DX9="lease",EG9,0),IF(ES9="lease",FB9,0),IF(FN9="lease",FW9,0),IF(GI9="lease",GR9,0),IF(HD9="lease",HM9,0),IF(HY9="lease",IH9,0),IF(IT9="lease",JC9,0)) -> 1.0581544 | T9: =SUM(IF(BM9="keep",BU9,0),IF(CH9="keep",CP9,0),IF(DC9="keep",DK9,0),IF(DX9="keep",EF9,0),IF(ES9="keep",FA9,0),IF(FN9="keep",FV9,0),IF(GI9="keep",GQ9,0),IF(HD9="keep",HL9,0),IF(HY9="keep",IG9,0),IF(IT9="keep",JB9,0)) -> 0 | U9: =SUM(IF(BM9="keep",BV9,0),IF(CH9="keep",CQ9,0),IF(DC9="keep",DL9,0),IF(DX9="keep",EG9,0),IF(ES9="keep",FB9,0),IF(FN9="keep",FW9,0),IF(GI9="keep",GR9,0),IF(HD9="keep",HM9,0),IF(HY9="keep",IH9,0),IF(IT9="keep",JC9,0)) -> 0 | V9: =R9/O9 -> 1.0166571 | W9: =S9/P9 -> 1.0277115 | X9: =T9/O9 -> 0 | Y9: =U9/P9 -> 0 | Z9: =V9+X9 -> 1.0166571 | AA9: =IFERROR(W9/V9-1,0) -> 0.010873252 | AB9: =IFERROR((W9-V9)/Z9,0) -> 0.010873252 | AC9: =IFERROR(Y9/X9-1,0) -> 0 | AD9: =IFERROR((Y9-X9)/Z9,0) -> 0 | AE9: =AB9+AD9 -> 0.010873252 | AF9: =(1+Q9)*(1+AE9)-1 -> -0.0019978082 | AG9: =G9-AF9 -> -8.5435131e-17 | AH9: =SUM(IF(BM9="lease",BW9,0),IF(CH9="lease",CR9,0),IF(DC9="lease",DM9,0),IF(DX9="lease",EH9,0),IF(ES9="lease",FC9,0),IF(FN9="lease",FX9,0),IF(GI9="lease",GS9,0),IF(HD9="lease",HN9,0),IF(HY9="lease",II9,0),IF(IT9="lease",JD9,0)) -> -0.0021182214 | AI9: =SUM(IF(BM9="keep",BW9,0),IF(CH9="keep",CR9,0),IF(DC9="keep",DM9,0),IF(DX9="keep",EH9,0),IF(ES9="keep",FC9,0),IF(FN9="keep",FX9,0),IF(GI9="keep",GS9,0),IF(HD9="keep",HN9,0),IF(HY9="keep",II9,0),IF(IT9="keep",JD9,0)) -> 0 | AJ9: =SUM(IF(BM9="lease",BX9,0),IF(CH9="lease",CS9,0),IF(DC9="lease",DN9,0),IF(DX9="lease",EI9,0),IF(ES9="lease",FD9,0),IF(FN9="lease",FY9,0),IF(GI9="lease",GT9,0),IF(HD9="lease",HO9,0),IF(HY9="lease",IJ9,0),IF(IT9="lease",JE9,0)) -> 0 | AK9: =SUM(IF(BM9="keep",BX9,0),IF(CH9="keep",CS9,0),IF(DC9="keep",DN9,0),IF(DX9="keep",EI9,0),IF(ES9="keep",FD9,0),IF(FN9="keep",FY9,0),IF(GI9="keep",GT9,0),IF(HD9="keep",HO9,0),IF(HY9="keep",IJ9,0),IF(IT9="keep",JE9,0)) -> 0 | AL9: =R9-S8 -> 0 | AM9: =T9-U8 -> 0 | AN9: =AN8 -> 1 | AO9: =AO8+AH9 -> 0.058154444 | AP9: =AP8+AL9 -> 0 | AQ9: =AN9+AO9+AP9 -> 1.0581544 | AR9: =S9-AQ9 -> 0 | AS9: =AS8 -> 0 | AT9: =AT8+AI9 -> 0 | AU9: =AU8+AM9 -> 0 | AV9: =AS9+AT9+AU9 -> 0 | AW9: =U9-AV9 -> 0 | AX9: 1.0602727 | AY9: 1.0581544 | AZ9: =S9-AY9 -> 0 | BA9: 0 | BB9: 0 | BC9: =U9-BB9 -> 0 | BD9: =SUM(IF(BL9="direct",CE9,0),IF(CG9="direct",CZ9,0),IF(DB9="direct",DU9,0),IF(DW9="direct",EP9,0),IF(ER9="direct",FK9,0),IF(FM9="direct",GF9,0),IF(GH9="direct",HA9,0),IF(HC9="direct",HV9,0),IF(HX9="direct",IQ9,0),IF(IS9="direct",JL9,0)) -> 0 | BE9: =SUM(IF(BL9="treasury",CE9,0),IF(CG9="treasury",CZ9,0),IF(DB9="treasury",DU9,0),IF(DW9="treasury",EP9,0),IF(ER9="treasury",FK9,0),IF(FM9="treasury",GF9,0),IF(GH9="treasury",HA9,0),IF(HC9="treasury",HV9,0),IF(HX9="treasury",IQ9,0),IF(IS9="treasury",JL9,0)) -> 0.00050219178 | BF9: =SUM(IF(BL9="future",CE9,0),IF(CG9="future",CZ9,0),IF(DB9="future",DU9,0),IF(DW9="future",EP9,0),IF(ER9="future",FK9,0),IF(FM9="future",GF9,0),IF(GH9="future",HA9,0),IF(HC9="future",HV9,0),IF(HX9="future",IQ9,0),IF(IS9="future",JL9,0)) -> -0.0025 | BG9: =SUM(IF(BL9="cash",CE9,0),IF(CG9="cash",CZ9,0),IF(DB9="cash",DU9,0),IF(DW9="cash",EP9,0),IF(ER9="cash",FK9,0),IF(FM9="cash",GF9,0),IF(GH9="cash",HA9,0),IF(HC9="cash",HV9,0),IF(HX9="cash",IQ9,0),IF(IS9="cash",JL9,0)) -> 0 | BH9: =SUM(BD9:BG9) -> -0.0019978082 | BI9: =G9-BH9 -> -4.3368087e-19 | BJ9: =COUNTA(BK9,CF9,DA9,DV9,EQ9,FL9,GG9,HB9,HW9,IR9) -> 4 | BK9: Treasury collateral | BL9: treasury | BM9: lease | BN9: long | BP9: 100.13514 | BQ9: 100.18543 | BR9: 0.010588417 | BS9: 1 | BT9: 1.0602727 | BU9: 1.0602727 | BV9: 1.0608051 | BW9: 0.00053246022 | BX9: 1.4419889e-17 | BY9: 2.042 | BZ9: 2.016 | CD9: 19 | CE9: =IFERROR(BW9/F9,0) -> 0.00050219178 | CF9: SI69F | CG9: future | CH9: lease | CI9: long | CJ9: regular | CK9: 2 | CL9: 1.995 | CM9: 0.53013633 | CN9: 1 | CO9: 1.0602727 | CP9: 0 | CQ9: 0 | CR9: -0.0026506817 | CS9: 0.0026506817 | CT9: 2.042 | CU9: 2.016 | CV9: -0.020568071 | CW9: 0.0611 | CX9: 0.45622346 | CY9: 19 | CZ9: =IFERROR(CR9/F9,0) -> -0.0025 | DA9: Lease cash / margin / financing | DB9: cash | DC9: lease | DD9: cash | DF9: 1 | DG9: 1 | DH9: 0 | DJ9: 0 | DK9: 0 | DL9: -0.0026506817 | DM9: 0 | DN9: -0.0026506817 | DO9: 2.042 | DP9: 2.016 | DU9: =IFERROR(DM9/F9,0) -> 0 | DV9: Keep cash / margin / financing | DW9: cash | DX9: keep | DY9: cash | EA9: 1 | EB9: 1 | EC9: 0 | EE9: 0 | EF9: 0 | EG9: 0 | EH9: 0 | EI9: 0 | EJ9: 2.042 | EK9: 2.016 | EP9: =IFERROR(EH9/F9,0) -> 0
A10: 25216 | B10: 25217 | C10: =B10-A10 -> 1 | D10: 25216 | E10: positive | F10: 1.0581544 | G10: 0.0086892485 | H10: =SUM(CE10,CZ10,DU10,EP10,FK10,GF10,HA10,HV10,IQ10,JL10) -> 0.0086892485 | I10: =G10-H10 -> 1.7347235e-18 | J10: =F10*(1+H10) -> 1.067349 | K10: 1.067349 | L10: =K10-J10 -> 0 | M10: 2.016 | N10: 2.027 | O10: =M10/$M$3 -> 1.0296221 | P10: =N10/$M$3 -> 1.03524 | Q10: =IFERROR(N10/M10-1,0) -> 0.0054563492 | R10: =SUM(IF(BM10="lease",BU10,0),IF(CH10="lease",CP10,0),IF(DC10="lease",DK10,0),IF(DX10="lease",EF10,0),IF(ES10="lease",FA10,0),IF(FN10="lease",FV10,0),IF(GI10="lease",GQ10,0),IF(HD10="lease",HL10,0),IF(HY10="lease",IG10,0),IF(IT10="lease",JB10,0)) -> 1.0581544 | S10: =SUM(IF(BM10="lease",BV10,0),IF(CH10="lease",CQ10,0),IF(DC10="lease",DL10,0),IF(DX10="lease",EG10,0),IF(ES10="lease",FB10,0),IF(FN10="lease",FW10,0),IF(GI10="lease",GR10,0),IF(HD10="lease",HM10,0),IF(HY10="lease",IH10,0),IF(IT10="lease",JC10,0)) -> 1.067349 | T10: =SUM(IF(BM10="keep",BU10,0),IF(CH10="keep",CP10,0),IF(DC10="keep",DK10,0),IF(DX10="keep",EF10,0),IF(ES10="keep",FA10,0),IF(FN10="keep",FV10,0),IF(GI10="keep",GQ10,0),IF(HD10="keep",HL10,0),IF(HY10="keep",IG10,0),IF(IT10="keep",JB10,0)) -> 0 | U10: =SUM(IF(BM10="keep",BV10,0),IF(CH10="keep",CQ10,0),IF(DC10="keep",DL10,0),IF(DX10="keep",EG10,0),IF(ES10="keep",FB10,0),IF(FN10="keep",FW10,0),IF(GI10="keep",GR10,0),IF(HD10="keep",HM10,0),IF(HY10="keep",IH10,0),IF(IT10="keep",JC10,0)) -> 0 | V10: =R10/O10 -> 1.0277115 | W10: =S10/P10 -> 1.031016 | X10: =T10/O10 -> 0 | Y10: =U10/P10 -> 0 | Z10: =V10+X10 -> 1.0277115 | AA10: =IFERROR(W10/V10-1,0) -> 0.0032153552 | AB10: =IFERROR((W10-V10)/Z10,0) -> 0.0032153552 | AC10: =IFERROR(Y10/X10-1,0) -> 0 | AD10: =IFERROR((Y10-X10)/Z10,0) -> 0 | AE10: =AB10+AD10 -> 0.0032153552 | AF10: =(1+Q10)*(1+AE10)-1 -> 0.0086892485 | AG10: =G10-AF10 -> 2.0469737e-16 | AH10: =SUM(IF(BM10="lease",BW10,0),IF(CH10="lease",CR10,0),IF(DC10="lease",DM10,0),IF(DX10="lease",EH10,0),IF(ES10="lease",FC10,0),IF(FN10="lease",FX10,0),IF(GI10="lease",GS10,0),IF(HD10="lease",HN10,0),IF(HY10="lease",II10,0),IF(IT10="lease",JD10,0)) -> 0.0091945669 | AI10: =SUM(IF(BM10="keep",BW10,0),IF(CH10="keep",CR10,0),IF(DC10="keep",DM10,0),IF(DX10="keep",EH10,0),IF(ES10="keep",FC10,0),IF(FN10="keep",FX10,0),IF(GI10="keep",GS10,0),IF(HD10="keep",HN10,0),IF(HY10="keep",II10,0),IF(IT10="keep",JD10,0)) -> 0 | AJ10: =SUM(IF(BM10="lease",BX10,0),IF(CH10="lease",CS10,0),IF(DC10="lease",DN10,0),IF(DX10="lease",EI10,0),IF(ES10="lease",FD10,0),IF(FN10="lease",FY10,0),IF(GI10="lease",GT10,0),IF(HD10="lease",HO10,0),IF(HY10="lease",IJ10,0),IF(IT10="lease",JE10,0)) -> 0 | AK10: =SUM(IF(BM10="keep",BX10,0),IF(CH10="keep",CS10,0),IF(DC10="keep",DN10,0),IF(DX10="keep",EI10,0),IF(ES10="keep",FD10,0),IF(FN10="keep",FY10,0),IF(GI10="keep",GT10,0),IF(HD10="keep",HO10,0),IF(HY10="keep",IJ10,0),IF(IT10="keep",JE10,0)) -> 0 | AL10: =R10-S9 -> 0 | AM10: =T10-U9 -> 0 | AN10: =AN9 -> 1 | AO10: =AO9+AH10 -> 0.06734901 | AP10: =AP9+AL10 -> 0 | AQ10: =AN10+AO10+AP10 -> 1.067349 | AR10: =S10-AQ10 -> 0 | AS10: =AS9 -> 0 | AT10: =AT9+AI10 -> 0 | AU10: =AU9+AM10 -> 0 | AV10: =AS10+AT10+AU10 -> 0 | AW10: =U10-AV10 -> 0 | AX10: 1.0581544 | AY10: 1.067349 | AZ10: =S10-AY10 -> 0 | BA10: 0 | BB10: 0 | BC10: =U10-BB10 -> 0 | BD10: =SUM(IF(BL10="direct",CE10,0),IF(CG10="direct",CZ10,0),IF(DB10="direct",DU10,0),IF(DW10="direct",EP10,0),IF(ER10="direct",FK10,0),IF(FM10="direct",GF10,0),IF(GH10="direct",HA10,0),IF(HC10="direct",HV10,0),IF(HX10="direct",IQ10,0),IF(IS10="direct",JL10,0)) -> 0 | BE10: =SUM(IF(BL10="treasury",CE10,0),IF(CG10="treasury",CZ10,0),IF(DB10="treasury",DU10,0),IF(DW10="treasury",EP10,0),IF(ER10="treasury",FK10,0),IF(FM10="treasury",GF10,0),IF(GH10="treasury",HA10,0),IF(HC10="treasury",HV10,0),IF(HX10="treasury",IQ10,0),IF(IS10="treasury",JL10,0)) -> 0.00016794521 | BF10: =SUM(IF(BL10="future",CE10,0),IF(CG10="future",CZ10,0),IF(DB10="future",DU10,0),IF(DW10="future",EP10,0),IF(ER10="future",FK10,0),IF(FM10="future",GF10,0),IF(GH10="future",HA10,0),IF(HC10="future",HV10,0),IF(HX10="future",IQ10,0),IF(IS10="future",JL10,0)) -> 0.0085213033 | BG10: =SUM(IF(BL10="cash",CE10,0),IF(CG10="cash",CZ10,0),IF(DB10="cash",DU10,0),IF(DW10="cash",EP10,0),IF(ER10="cash",FK10,0),IF(FM10="cash",GF10,0),IF(GH10="cash",HA10,0),IF(HC10="cash",HV10,0),IF(HX10="cash",IQ10,0),IF(IS10="cash",JL10,0)) -> 0 | BH10: =SUM(BD10:BG10) -> 0.0086892485 | BI10: =G10-BH10 -> 1.7347235e-18 | BJ10: =COUNTA(BK10,CF10,DA10,DV10,EQ10,FL10,GG10,HB10,HW10,IR10) -> 4 | BK10: Treasury collateral | BL10: treasury | BM10: lease | BN10: long | BP10: 100.18543 | BQ10: 100.20225 | BR10: 0.01056196 | BS10: 1 | BT10: 1.0581544 | BU10: 1.0581544 | BV10: 1.0583322 | BW10: 0.00017771197 | BX10: -9.2645076e-17 | BY10: 2.016 | BZ10: 2.027 | CD10: 16 | CE10: =IFERROR(BW10/F10,0) -> 0.00016794521 | CF10: SI69F | CG10: future | CH10: lease | CI10: long | CJ10: regular | CK10: 1.995 | CL10: 2.012 | CM10: 0.53040323 | CN10: 1 | CO10: 1.0581544 | CP10: 0 | CQ10: 0 | CR10: 0.0090168549 | CS10: -0.0090168549 | CT10: 2.016 | CU10: 2.027 | CV10: -0.010416667 | CW10: 0.0613 | CX10: 0.29893021 | CY10: 16 | CZ10: =IFERROR(CR10/F10,0) -> 0.0085213033 | DA10: Lease cash / margin / financing | DB10: cash | DC10: lease | DD10: cash | DF10: 1 | DG10: 1 | DH10: 0 | DJ10: 0 | DK10: 0 | DL10: 0.0090168549 | DM10: 0 | DN10: 0.0090168549 | DO10: 2.016 | DP10: 2.027 | DU10: =IFERROR(DM10/F10,0) -> 0 | DV10: Keep cash / margin / financing | DW10: cash | DX10: keep | DY10: cash | EA10: 1 | EB10: 1 | EC10: 0 | EE10: 0 | EF10: 0 | EG10: 0 | EH10: 0 | EI10: 0 | EJ10: 2.016 | EK10: 2.027 | EP10: =IFERROR(EH10/F10,0) -> 0
A11: 25217 | B11: 25218 | C11: =B11-A11 -> 1 | D11: 25217 | E11: positive | F11: 1.067349 | G11: -0.0028127923 | H11: =SUM(CE11,CZ11,DU11,EP11,FK11,GF11,HA11,HV11,IQ11,JL11) -> -0.0028127923 | I11: =G11-H11 -> -4.3368087e-19 | J11: =F11*(1+H11) -> 1.0643468 | K11: 1.0643468 | L11: =K11-J11 -> 0 | M11: 2.027 | N11: 2.038 | O11: =M11/$M$3 -> 1.03524 | P11: =N11/$M$3 -> 1.040858 | Q11: =IFERROR(N11/M11-1,0) -> 0.005426739 | R11: =SUM(IF(BM11="lease",BU11,0),IF(CH11="lease",CP11,0),IF(DC11="lease",DK11,0),IF(DX11="lease",EF11,0),IF(ES11="lease",FA11,0),IF(FN11="lease",FV11,0),IF(GI11="lease",GQ11,0),IF(HD11="lease",HL11,0),IF(HY11="lease",IG11,0),IF(IT11="lease",JB11,0)) -> 1.067349 | S11: =SUM(IF(BM11="lease",BV11,0),IF(CH11="lease",CQ11,0),IF(DC11="lease",DL11,0),IF(DX11="lease",EG11,0),IF(ES11="lease",FB11,0),IF(FN11="lease",FW11,0),IF(GI11="lease",GR11,0),IF(HD11="lease",HM11,0),IF(HY11="lease",IH11,0),IF(IT11="lease",JC11,0)) -> 1.0643468 | T11: =SUM(IF(BM11="keep",BU11,0),IF(CH11="keep",CP11,0),IF(DC11="keep",DK11,0),IF(DX11="keep",EF11,0),IF(ES11="keep",FA11,0),IF(FN11="keep",FV11,0),IF(GI11="keep",GQ11,0),IF(HD11="keep",HL11,0),IF(HY11="keep",IG11,0),IF(IT11="keep",JB11,0)) -> 0 | U11: =SUM(IF(BM11="keep",BV11,0),IF(CH11="keep",CQ11,0),IF(DC11="keep",DL11,0),IF(DX11="keep",EG11,0),IF(ES11="keep",FB11,0),IF(FN11="keep",FW11,0),IF(GI11="keep",GR11,0),IF(HD11="keep",HM11,0),IF(HY11="keep",IH11,0),IF(IT11="keep",JC11,0)) -> 0 | V11: =R11/O11 -> 1.031016 | W11: =S11/P11 -> 1.0225667 | X11: =T11/O11 -> 0 | Y11: =U11/P11 -> 0 | Z11: =V11+X11 -> 1.031016 | AA11: =IFERROR(W11/V11-1,0) -> -0.0081950589 | AB11: =IFERROR((W11-V11)/Z11,0) -> -0.0081950589 | AC11: =IFERROR(Y11/X11-1,0) -> 0 | AD11: =IFERROR((Y11-X11)/Z11,0) -> 0 | AE11: =AB11+AD11 -> -0.0081950589 | AF11: =(1+Q11)*(1+AE11)-1 -> -0.0028127923 | AG11: =G11-AF11 -> 1.0278237e-16 | AH11: =SUM(IF(BM11="lease",BW11,0),IF(CH11="lease",CR11,0),IF(DC11="lease",DM11,0),IF(DX11="lease",EH11,0),IF(ES11="lease",FC11,0),IF(FN11="lease",FX11,0),IF(GI11="lease",GS11,0),IF(HD11="lease",HN11,0),IF(HY11="lease",II11,0),IF(IT11="lease",JD11,0)) -> -0.0030022311 | AI11: =SUM(IF(BM11="keep",BW11,0),IF(CH11="keep",CR11,0),IF(DC11="keep",DM11,0),IF(DX11="keep",EH11,0),IF(ES11="keep",FC11,0),IF(FN11="keep",FX11,0),IF(GI11="keep",GS11,0),IF(HD11="keep",HN11,0),IF(HY11="keep",II11,0),IF(IT11="keep",JD11,0)) -> 0 | AJ11: =SUM(IF(BM11="lease",BX11,0),IF(CH11="lease",CS11,0),IF(DC11="lease",DN11,0),IF(DX11="lease",EI11,0),IF(ES11="lease",FD11,0),IF(FN11="lease",FY11,0),IF(GI11="lease",GT11,0),IF(HD11="lease",HO11,0),IF(HY11="lease",IJ11,0),IF(IT11="lease",JE11,0)) -> 0 | AK11: =SUM(IF(BM11="keep",BX11,0),IF(CH11="keep",CS11,0),IF(DC11="keep",DN11,0),IF(DX11="keep",EI11,0),IF(ES11="keep",FD11,0),IF(FN11="keep",FY11,0),IF(GI11="keep",GT11,0),IF(HD11="keep",HO11,0),IF(HY11="keep",IJ11,0),IF(IT11="keep",JE11,0)) -> 0 | AL11: =R11-S10 -> 0 | AM11: =T11-U10 -> 0 | AN11: =AN10 -> 1 | AO11: =AO10+AH11 -> 0.064346779 | AP11: =AP10+AL11 -> 0 | AQ11: =AN11+AO11+AP11 -> 1.0643468 | AR11: =S11-AQ11 -> 0 | AS11: =AS10 -> 0 | AT11: =AT10+AI11 -> 0 | AU11: =AU10+AM11 -> 0 | AV11: =AS11+AT11+AU11 -> 0 | AW11: =U11-AV11 -> 0 | AX11: 1.067349 | AY11: 1.0643468 | AZ11: =S11-AY11 -> 0 | BA11: 0 | BB11: 0 | BC11: =U11-BB11 -> 0 | BD11: =SUM(IF(BL11="direct",CE11,0),IF(CG11="direct",CZ11,0),IF(DB11="direct",DU11,0),IF(DW11="direct",EP11,0),IF(ER11="direct",FK11,0),IF(FM11="direct",GF11,0),IF(GH11="direct",HA11,0),IF(HC11="direct",HV11,0),IF(HX11="direct",IQ11,0),IF(IS11="direct",JL11,0)) -> 0 | BE11: =SUM(IF(BL11="treasury",CE11,0),IF(CG11="treasury",CZ11,0),IF(DB11="treasury",DU11,0),IF(DW11="treasury",EP11,0),IF(ER11="treasury",FK11,0),IF(FM11="treasury",GF11,0),IF(GH11="treasury",HA11,0),IF(HC11="treasury",HV11,0),IF(HX11="treasury",IQ11,0),IF(IS11="treasury",JL11,0)) -> 0.00016931507 | BF11: =SUM(IF(BL11="future",CE11,0),IF(CG11="future",CZ11,0),IF(DB11="future",DU11,0),IF(DW11="future",EP11,0),IF(ER11="future",FK11,0),IF(FM11="future",GF11,0),IF(GH11="future",HA11,0),IF(HC11="future",HV11,0),IF(HX11="future",IQ11,0),IF(IS11="future",JL11,0)) -> -0.0029821074 | BG11: =SUM(IF(BL11="cash",CE11,0),IF(CG11="cash",CZ11,0),IF(DB11="cash",DU11,0),IF(DW11="cash",EP11,0),IF(ER11="cash",FK11,0),IF(FM11="cash",GF11,0),IF(GH11="cash",HA11,0),IF(HC11="cash",HV11,0),IF(HX11="cash",IQ11,0),IF(IS11="cash",JL11,0)) -> 0 | BH11: =SUM(BD11:BG11) -> -0.0028127923 | BI11: =G11-BH11 -> -4.3368087e-19 | BJ11: =COUNTA(BK11,CF11,DA11,DV11,EQ11,FL11,GG11,HB11,HW11,IR11) -> 4 | BK11: Treasury collateral | BL11: treasury | BM11: lease | BN11: long | BP11: 100.20225 | BQ11: 100.21922 | BR11: 0.010651946 | BS11: 1 | BT11: 1.067349 | BU11: 1.067349 | BV11: 1.0675297 | BW11: 0.00018071827 | BX11: -2.4015078e-17 | BY11: 2.027 | BZ11: 2.038 | CD11: 15 | CE11: =IFERROR(BW11/F11,0) -> 0.00016931507 | CF11: SI69F | CG11: future | CH11: lease | CI11: long | CJ11: regular | CK11: 2.012 | CL11: 2.006 | CM11: 0.53049156 | CN11: 1 | CO11: 1.067349 | CP11: 0 | CQ11: 0 | CR11: -0.0031829493 | CS11: 0.0031829493 | CT11: 2.027 | CU11: 2.038 | CV11: -0.0074000987 | CW11: 0.0618 | CX11: 0.24186907 | CY11: 15 | CZ11: =IFERROR(CR11/F11,0) -> -0.0029821074 | DA11: Lease cash / margin / financing | DB11: cash | DC11: lease | DD11: cash | DF11: 1 | DG11: 1 | DH11: 0 | DJ11: 0 | DK11: 0 | DL11: -0.0031829493 | DM11: 0 | DN11: -0.0031829493 | DO11: 2.027 | DP11: 2.038 | DU11: =IFERROR(DM11/F11,0) -> 0 | DV11: Keep cash / margin / financing | DW11: cash | DX11: keep | DY11: cash | EA11: 1 | EB11: 1 | EC11: 0 | EE11: 0 | EF11: 0 | EG11: 0 | EH11: 0 | EI11: 0 | EJ11: 2.027 | EK11: 2.038 | EP11: =IFERROR(EH11/F11,0) -> 0
